C:\Users\danie\AppData\Local\Programs\Python\Python311\Lib\site-packages\keras\src\layers\rnn\rnn.py:200: UserWarning: Do not pass an `input_shape`/`input_dim` argument to a layer. When using Sequential models, prefer using an `Input(shape)` object as the first layer in the model instead.
  super().__init__(**kwargs)
[34m[1mwandb[0m: [33mWARNING[0m WandbCallback is deprecated and will be removed in a future release. Please use the WandbMetricsLogger, WandbModelCheckpoint, and WandbEvalCallback callbacks instead. See https://docs.wandb.ai/guides/integrations/keras for more information.
Epoch 1/10
Traceback (most recent call last):
  File "c:\Users\danie\OneDrive\Desktop\INM706-Code-1\train.py", line 40, in <module>
    history = model.fit(
              ^^^^^^^^^^
  File "C:\Users\danie\AppData\Local\Programs\Python\Python311\Lib\site-packages\keras\src\utils\traceback_utils.py", line 122, in error_handler
    raise e.with_traceback(filtered_tb) from None
  File "C:\Users\danie\AppData\Local\Programs\Python\Python311\Lib\site-packages\wandb\integration\keras\keras.py", line 668, in on_train_batch_end
    wandb.run.summary["graph"] = wandb.Graph.from_keras(self.model)
                                 ^^^^^^^^^^^^^^^^^^^^^^^^^^^^^^^^^^
  File "C:\Users\danie\AppData\Local\Programs\Python\Python311\Lib\site-packages\wandb\sdk\data_types\graph.py", line 357, in from_keras
    for in_layer in _nest(in_node.inbound_layers):
                          ^^^^^^^^^^^^^^^^^^^^^^
AttributeError: 'Node' object has no attribute 'inbound_layers'
